Workbook

Sheet Summary
A1: OrderFlow (.NET) Project Tracker: Summary
A2: Everything here is calculated from the Done columns on the other sheets. Nothing to edit on this sheet.
A4: Section | B4: Done | C4: Total | D4: % done
A5: Goals achieved | B5: =COUNTIF(Goals!D5:D15,"Yes") -> 0 | C5: =COUNTA(Goals!B5:B15) -> 11 | D5: =IF(C5=0,0,B5/C5) -> 0
A6: Implementation items | B6: =COUNTIF(Implementation!F5:F74,"Yes") -> 0 | C6: =COUNTA(Implementation!D5:D74) -> 70 | D6: =IF(C6=0,0,B6/C6) -> 0
A7: Concepts I can explain | B7: =COUNTIF(Concepts!G5:G50,"Yes") -> 0 | C7: =COUNTA(Concepts!C5:C50) -> 46 | D7: =IF(C7=0,0,B7/C7) -> 0
A8: Final checklist | B8: =COUNTIF('Final Checklist'!D5:D29,"Yes") -> 0 | C8: =COUNTA('Final Checklist'!C5:C29) -> 25 | D8: =IF(C8=0,0,B8/C8) -> 0
A11: Implementation progress by week
A12: Week | B12: Done | C12: Total | D12: % done
A13: Week 1 | B13: =COUNTIFS(Implementation!$B$5:$B$74,A13,Implementation!$F$5:$F$74,"Yes") -> 0 | C13: =COUNTIF(Implementation!$B$5:$B$74,A13) -> 15 | D13: =IF(C13=0,0,B13/C13) -> 0
A14: Week 2 | B14: =COUNTIFS(Implementation!$B$5:$B$74,A14,Implementation!$F$5:$F$74,"Yes") -> 0 | C14: =COUNTIF(Implementation!$B$5:$B$74,A14) -> 17 | D14: =IF(C14=0,0,B14/C14) -> 0
A15: Week 3 | B15: =COUNTIFS(Implementation!$B$5:$B$74,A15,Implementation!$F$5:$F$74,"Yes") -> 0 | C15: =COUNTIF(Implementation!$B$5:$B$74,A15) -> 12 | D15: =IF(C15=0,0,B15/C15) -> 0
A16: Week 4 | B16: =COUNTIFS(Implementation!$B$5:$B$74,A16,Implementation!$F$5:$F$74,"Yes") -> 0 | C16: =COUNTIF(Implementation!$B$5:$B$74,A16) -> 12 | D16: =IF(C16=0,0,B16/C16) -> 0
A17: Week 5 | B17: =COUNTIFS(Implementation!$B$5:$B$74,A17,Implementation!$F$5:$F$74,"Yes") -> 0 | C17: =COUNTIF(Implementation!$B$5:$B$74,A17) -> 11 | D17: =IF(C17=0,0,B17/C17) -> 0
A18: Week 6 | B18: =COUNTIFS(Implementation!$B$5:$B$74,A18,Implementation!$F$5:$F$74,"Yes") -> 0 | C18: =COUNTIF(Implementation!$B$5:$B$74,A18) -> 3 | D18: =IF(C18=0,0,B18/C18) -> 0
A19: All weeks | B19: =SUM(B13:B18) -> 0 | C19: =SUM(C13:C18) -> 70 | D19: =IF(C19=0,0,B19/C19) -> 0
A21: Check: week totals match the Implementation total | C21: =IF(C19=C6,"OK","Mismatch") -> OK
A22: Week 6 is an optional buffer (Kafka, Kubernetes, LLM feature). Do it only after weeks 1-5 are finished.

Sheet Goals
A1: What OrderFlow (.NET) will achieve
A2: Legend: yellow = edit. Set Done to Yes (dropdown) when you can demonstrate the 'How you'll prove it' column. Example Notes: 'Verified with 3 test orders on 12 Nov'.
A4: # | B4: Goal (what the project achieves) | C4: How you'll prove it | D4: Done? | E4: Notes
A5: 1 | B5: Customers can browse stock and place an order through a secured REST API behind one gateway | C5: Get a JWT, call POST /orders through the YARP gateway, and see the order in the Order database | D5: No
A6: 2 | B6: An order flows Order > Inventory > Payment > Notification asynchronously through RabbitMQ | C6: Place one order and watch the messages move through all four services in the logs | D6: No
A7: 3 | B7: No lost or duplicated orders, even when a service crashes mid-order | C7: Kill a service mid-flow and restart it: order still completes once, customer charged once | D7: No
A8: 4 | B8: Failures compensate cleanly (payment failed, stock released) | C8: Force a payment failure: order ends CANCELLED and the reserved stock is released | D8: No
A9: 5 | B9: Stock never oversells under concurrency | C9: Two simultaneous orders for the last unit: exactly one succeeds, one is rejected | D9: No
A10: 6 | B10: Hot reads are fast and the system survives a slow or dead dependency | C10: Cache hit visible in Redis; Polly circuit breaker opens when Inventory is down | D10: No
A11: 7 | B11: One order can be traced across every service | C11: One trace ID in Jaeger and in all service logs for a single order | D11: No
A12: 8 | B12: Whole system runs with one command locally and is deployed to Azure | C12: docker compose up works from a clean clone; the live URL on Azure Container Apps answers | D12: No
A13: 9 | B13: Every push is built and tested automatically, on real infrastructure | C13: Green GitHub Actions run using Testcontainers (Postgres, RabbitMQ) | D13: No
A14: 10 | B14: You have real performance numbers | C14: k6 results recorded: orders/sec, p95 latency and error rate, with and without cache | D14: No
A15: 11 | B15: The project is interview-ready | C15: README, diagrams, trade-offs section and failure drills exist and you can explain each decision | D15: No

Sheet Implementation
A1: What to implement, week by week (.NET 8)
A2: Legend: yellow = edit. Set Done to Yes (dropdown) only when the 'Done when' column is true. Example Notes: 'Used Testcontainers 3.x; flaky on first run'.
A4: # | B4: Week | C4: Area | D4: What to implement | E4: Done when | F4: Done? | G4: Notes
A5: 1 | B5: Week 1 | C5: Setup | D5: Install .NET 8 SDK, Visual Studio or Rider, Docker Desktop, Git | E5: dotnet --version, docker ps and git --version all work | F5: No
A6: 2 | B6: Week 1 | C6: Setup | D6: Create the solution: src/ folder per service, shared Contracts project, docker-compose.yml, docs/ | E6: dotnet build on the solution succeeds | F6: No
A7: 3 | B7: Week 1 | C7: Platform | D7: PostgreSQL containers in Docker Compose, one database per service | E7: Two databases running with separate credentials; no shared tables | F7: No
A8: 4 | B8: Week 1 | C8: Contracts | D8: Shared Contracts project with message records (SubmitOrder, StockReserved, PaymentFailed and so on) | E8: Contracts project referenced by every service and builds | F8: No
A9: 5 | B9: Week 1 | C9: Inventory Service | D9: Create Inventory Service with Clean Architecture layers (Api, Application, Domain, Infrastructure) | E9: Project references only point inward; service starts | F9: No
A10: 6 | B10: Week 1 | C10: Inventory Service | D10: StockItem entity, EF Core DbContext and first migration | E10: Table created by migration; rows saved and read | F10: No
A11: 7 | B11: Week 1 | C11: Inventory Service | D11: CRUD endpoints with request/response DTOs and FluentValidation | E11: GET, POST, PUT, DELETE work; invalid input returns 400 with field errors | F11: No
A12: 8 | B12: Week 1 | C12: Order Service | D12: Create Order Service with the same layers; Order and OrderItem entities plus status enum (Pending, Confirmed, Cancelled) | E12: Status stored and returned correctly | F12: No
A13: 9 | B13: Week 1 | C13: Order Service | D13: EF Core migration against its own database | E13: Separate DB; no shared tables with Inventory | F13: No
A14: 10 | B14: Week 1 | C14: Order Service | D14: Create, get and list order endpoints with DTOs and validation | E14: Order created via API and visible in the database | F14: No
A15: 11 | B15: Week 1 | C15: Order Service | D15: Pagination on the order list (page and size; note keyset as the alternative) | E15: Page 2 returns the next set; total count included | F15: No
A16: 12 | B16: Week 1 | C16: Platform | D16: Global exception handling returning ProblemDetails | E16: 404, 400, 409 and 500 all return the same JSON shape | F16: No
... A74: 70 | B74: Week 6 | C74: Optional | D74: LLM-powered feature, e.g. natural-language order search or a support summarizer | E74: Feature works against a real LLM API call | F74: No

Sheet DAY CHECKER
A1: OrderFlow (.NET): Day-by-Day Build Plan
A3: 30 build days across 5 weeks (plus 3 optional days in week 6), mapped to the Implementation sheet. Assumes about 1.5-2 hours on weekdays and a longer block on the weekend, roughly 12-15 hours a week. Day 6 of each week is the weekend block.
A5: How we work each day
A7: 1. You send: the previous day's solution as a zip, plus a message like "Day 4". Exclude bin/, obj/, .vs/, .git/ and any .env files with real secrets.
A8: 2. I send back: the goal for the day, the concepts in plain language, the code file by file, the commands to run, the exact "Done when" check from your tracker, and 3 interview-style questions.
A9: 3. You do: type or paste the code (typing beats pasting for learning), run it, break it on purpose once, and confirm the "Done when" check passes. Use an AI assistant for boilerplate, and spend your own time on design decisions.
A10: 4. You update the tracker: set Done to Yes only when the check is true. Set "Can I explain it?" to Yes only when you can explain the concept out loud without notes.
A11: 5. If something fails: send me the error text or a screenshot plus the zip, and we fix it before moving on.
A12: The zip lets me match your namespaces, package versions and existing code, so each day's code fits what you already have.
A14: Scope reminder
A15: 4 services plus a gateway (Order, Inventory, Payment, Notification, YARP). One saga. No frontend, no admin panel. If you fall behind, cut Notification or Redis, never the tests or the saga.
A17: Week 1: Foundation and first two services
A19: Day | B19: We build | C19: Concepts we learn | D19: Tracker items
A20: 1 | B20: Setup, solution structure | C20: Solution and project structure, why a shared Contracts project | D20: 1-2
A21: 2 | B21: Compose Postgres, contracts, Inventory project | C21: Database per service, Clean Architecture layers | D21: 3-5
A22: 3 | B22: Inventory entity, migrations, CRUD endpoints | C22: EF Core change tracking and migrations, REST status codes, validation | D22: 6-7
A23: 4 | B23: Order Service project, entities, migration | C23: DI lifetimes, Options pattern, N+1 problem | D23: 8-9
A24: 5 | B24: Order endpoints and pagination | C24: Projections and AsNoTracking, offset vs keyset pagination | D24: 10-11
A25: 6 | B25: Error handling, logging, health, Dockerfiles (weekend block) | C25: Middleware pipeline, ProblemDetails, structured logging, multi-stage builds | D25: 12-15
A27: Week 2: Messaging and reliability
A29: Day | B29: We build | C29: Concepts we learn | D29: Tracker items
A30: 7 | B30: RabbitMQ and MassTransit, Payment and Notification services | C30: Exchanges, queues, bindings, acks; events vs commands | D30: 16-18
A31: 8 | B31: Inventory consumers, reproduce failures, Order outbox | C31: Dual-write problem, transactional outbox | D31: 19-21
A32: 9 | B32: Outbox for other services, saga state | C32: Saga orchestration vs choreography, persisted state | D32: 22-23
A33: 10 | B33: Saga happy path and payment-failure compensation | C33: Compensation, eventual consistency, why 2PC is avoided | D33: 24-25
A34: 11 | B34: Invalid transitions, notifications, idempotent consumers | C34: Inbox pattern, idempotency, delivery semantics | D34: 26-28
A35: 12 | B35: Retries, error queue, kill test, decision notes (weekend block) | C35: Backoff and jitter, poison messages, CAP basics | D35: 29-32
A37: Week 3: Gateway, security, performance
A39: Day | B39: We build | C39: Concepts we learn | D39: Tracker items
A40: 13 | B40: YARP gateway and rate limiting | C40: API gateway pattern, rate limiting | D40: 33-34
A41: 14 | B41: JWT at the gateway and role policies | C41: AuthN vs AuthZ, 401 vs 403, JWT structure, OAuth 2.0 and OIDC, Entra ID | D41: 35-36
A42: 15 | B42: Redis cache-aside and invalidation | C42: Cache-aside, TTL, invalidation, stampede | D42: 37-38
A43: 16 | B43: Optimistic concurrency and the last-unit demo | C43: Optimistic vs pessimistic concurrency, isolation levels | D43: 39-40
A44: 17 | B44: Dapper hot query, execution plan, API versioning | C44: Indexing and execution plans, Dapper vs EF Core, API versioning | D44: 41-42
A45: 18 | B45: Polly resilience, decision notes (weekend block) | C45: HttpClientFactory, circuit breaker states, timeouts and retry storms | D45: 43-44
A47: Week 4: Quality and observability
A49: Day | B49: We build | C49: Concepts we learn | D49: Tracker items
A50: 19 | B50: Unit tests and saga harness tests | C50: Test pyramid, testing sagas with the MassTransit harness | D50: 45-46
A51: 20 | B51: Testcontainers with Postgres, concurrency test | C51: Why Testcontainers instead of mocks or in-memory databases | D51: 47-48
A52: 21 | B52: End-to-end test with RabbitMQ | C52: Integration vs unit tests, test isolation | D52: 49
...

Sheet Concepts
A1: Concepts to understand and explain
A2: Legend: yellow = edit. Set 'Can I explain it?' to Yes only when you can explain it out loud, without notes, using OrderFlow as the example. Example Notes: 'Re-read outbox article; explain with diagram'.
A4: # | B4: Category | C4: Concept | D4: Where it shows up in OrderFlow | E4: When | F4: Practice question (interview style) | G4: Can I explain it? | H4: Notes
A5: 1 | B5: C# / .NET | C5: Dependency injection lifetimes (singleton, scoped, transient) and captive dependencies | D5: Every service | E5: Week 1 | F5: What happens if you inject a scoped service into a singleton? | G5: No
A6: 2 | B6: C# / .NET | C6: Middleware pipeline and why order matters | D6: APIs and gateway | E6: Week 1 | F6: Why does the order of app.Use calls matter? | G6: No
A7: 3 | B7: C# / .NET | C7: async/await and CancellationToken | D7: Every endpoint | E7: Week 1 | F7: What does await do, and why pass a CancellationToken? | G7: No
A8: 4 | B8: C# / .NET | C8: Options pattern and configuration | D8: Compose, Azure | E8: Week 1 | F8: How do you run the same build in dev and prod? | G8: No
A9: 5 | B9: C# / .NET | C9: Minimal APIs vs controllers | D9: Services | E9: Week 1 | F9: When would you choose each? | G9: No
A10: 6 | B10: C# / .NET | C10: Background services and hosted services | D10: MassTransit, outbox delivery | E10: Week 2 | F10: How does a BackgroundService differ from a request handler? | G10: No
A11: 7 | B11: C# / .NET | C11: HttpClientFactory with Polly | D11: Order > Inventory call | E11: Week 3 | F11: Why not new HttpClient() per request? | G11: No
A12: 8 | B12: Data | C12: EF Core change tracking, AsNoTracking, projections | D12: Order and Inventory | E12: Week 1 | F12: When do you use AsNoTracking? | G12: No
A13: 9 | B13: Data | C13: N+1 problem and how to fix it | D13: Order + OrderItem | E13: Week 1 | F13: What is N+1 and how do you spot it? | G13: No
A14: 10 | B14: Data | C14: Migrations and why the schema is code | D14: Every service | E14: Week 1 | F14: How do you ship a schema change safely? | G14: No
A15: 11 | B15: Data | C15: Database per service | D15: Every service | E15: Week 1 | F15: Why not one shared database? | G15: No
A16: 12 | B16: Data | C16: Pagination: offset vs keyset | D16: Order list | E16: Week 1 | F16: Why does offset pagination get slow on large tables? | G16: No
... A50: 46 | B50: Infrastructure | C50: What changes at 100x scale | D50: README trade-offs | E50: Week 5 | F50: Where does your design break first, and what would you change? | G50: No

Sheet Final Checklist
A1: Final checklist: what must exist before you call OrderFlow done
A2: Legend: yellow = edit. Set Done to Yes (dropdown) when it's true in your repo. Example Notes: 'Badge added 20 Dec'.
A4: # | B4: Category | C4: Item | D4: Done? | E4: Notes
A5: 1 | B5: Repo | C5: docker compose up works from a clean clone with one command | D5: No
A6: 2 | B6: Repo | C6: No secrets, passwords or tokens committed | D6: No
A7: 3 | B7: Repo | C7: Clear folder structure: one folder per service, plus Contracts, docs/ and tests/ | D7: No
A8: 4 | B8: Repo | C8: Green CI badge in README | D8: No
A9: 5 | B9: Services | C9: Order, Inventory, Payment and Notification services each run and expose health | D9: No
A10: 6 | B10: Services | C10: Each service has its own database with EF Core migrations | D10: No
A11: 7 | B11: Services | C11: Swagger available for each REST service | D11: No
A12: 8 | B12: Services | C12: YARP gateway with JWT auth and at least two roles | D12: No
A13: 9 | B13: Messaging | C13: RabbitMQ with MassTransit and EF Core transactional outbox | D13: No
A14: 10 | B14: Messaging | C14: Idempotent consumers (inbox or message-id check) | D14: No
A15: 11 | B15: Messaging | C15: Saga with compensation; invalid state transitions rejected | D15: No
A16: 12 | B16: Messaging | C16: Retries with backoff and error queue configured | D16: No
... A29: 25 | B29: Interview | C29: You can explain every decision note and every concept in the Concepts sheet out loud | D29: No
